Workbook
Name UPDATE: 'Data Sheet'!$E$1

Sheet Input
A2: Company Description | B2: ITC Limited is a leading Indian diversified company headquartered in Kolkata, established in 1910. It operates across multiple business segments including FMCG (foods and personal care), cigarettes, hotels, paper & packaging, and agri-business. While a large share of its profits still comes from the cigarette segment, its FMCG division is growing rapidly with popular brands like Aashirvaad and Sunfeast.The company has a strong distribution network across India and focuses on sustainability initiatives.

Sheet Input Sheet
B2: DATE | C2: CLOSE | D2: VOLUME
B3: 46113 | C3: 291.7 | D3: 18.60434
B4: 46111 | C4: 287.7 | D4: 24.586921
B5: 46108 | C5: 294.7 | D5: 22.179022
B6: 46106 | C6: 295.7 | D6: 26.184716
B7: 46105 | C7: 291.25 | D7: 33.335721
B8: 46104 | C8: 290.45 | D8: 31.78816
B9: 46101 | C9: 299.95 | D9: 58.679529
B10: 46100 | C10: 298 | D10: 17.851126
B11: 46099 | C11: 304.05 | D11: 16.702554
B12: 46098 | C12: 304.85 | D12: 25.649286
B13: 46097 | C13: 308.25 | D13: 37.472204
B14: 46094 | C14: 301.45 | D14: 25.659996 | H14: 10000000 | I14: 100
B15: 46093 | C15: 304.1 | D15: 23.319679
B16: 46092 | C16: 309 | D16: 14.842485 | F16: Shareholder's name | G16: No.of Share (In crs.) | H16: % Holding | I16: Market Value (In Crs.)
B17: 46091 | C17: 309.05 | D17: 18.35295 | F17: Tobacco Manufacturers (India) Limited | G17: 222.84959 | H17: 0.1779 | I17: =291.4*G17 -> 64938.369
B18: 46090 | C18: 306 | D18: 14.084931 | F18: Life Insurance Corporation of India | G18: 196.57974 | H18: 0.1569 | I18: =291.4*G18 -> 57283.335
B19: 46087 | C19: 309.7 | D19: 21.288269 | F19: Specified Undertaking of the Unit Trust of India | G19: 97.453143 | H19: 0.0778 | I19: =291.4*G19 -> 28397.846
B20: 46086 | C20: 311.5 | D20: 19.938009 | F20: Myddleton Investment Company Limited | G20: 48.631194 | H20: 0.0388 | I20: =291.4*G20 -> 14171.13 | L20: Segment | M20: Revenue (₹ Cr) | N20: % Contribution
B21: 46085 | C21: 311.95 | D21: 24.165489 | F21: SBI Mutual Funds | G21: 41.195289 | H21: 0.0329 | I21: =291.4*G21 -> 12004.307 | L21: Cigarettes | M21: 32500 | N21: 0.43
B22: 46083 | C22: 314.9 | D22: 22.194311 | F22: ICICI Prudential Mutual Funds | G22: 38.82518 | H22: 0.031 | I22: =291.4*G22 -> 11313.658 | L22: FMCG (Non-Cig) | M22: 22000 | N22: 0.29
B23: 46080 | C23: 313.6 | D23: 13.892595 | F23: QIB - Insurance Company Registered | G23: 31.281378 | H23: 0.025 | I23: =291.4*G23 -> 9115.3936 | L23: Agri Business | M23: 15000 | N23: 0.2
B24: 46079 | C24: 318.3 | D24: 11.270119 | F24: GQG Partners Emerging Markets Equity Fund | G24: 22.380053 | H24: 0.0179 | I24: =291.4*G24 -> 6521.5474 | L24: Paper & Packaging | M24: 5000 | N24: 0.07
B25: 46078 | C25: 319.75 | D25: 13.492101 | F25: General Insurance Corporation of India | G25: 21.708551 | H25: 0.0173 | I25: =291.4*G25 -> 6325.8717 | L25: Hotels | M25: 800 | N25: 0.01
B26: 46077 | C26: 323.5 | D26: 13.135859 | F26: NPS Trust (various Pension Funds) | G26: 20.23053 | H26: 0.0162 | I26: =291.4*G26 -> 5895.1763 | L26: Total | M26: 75300 | N26: 1
B27: 46076 | C27: 325.4 | D27: 13.486092
B28: 46073 | C28: 327 | D28: 11.282027 | F28: FIIs | G28: 0.3611
B29: 46072 | C29: 326 | D29: 19.911747 | F29: DIIs | G29: 0.489
B30: 46071 | C30: 332.45 | D30: 35.473203 | F30: Public & Gov. | G30: =14.99% -> 0.1499
B31: 46070 | C31: 325.45 | D31: 39.360672
B32: 46069 | C32: 317.95 | D32: 11.693763
B33: 46066 | C33: 313.75 | D33: 8.730618
B34: 46065 | C34: 317.45 | D34: 13.294561
B35: 46064 | C35: 318.25 | D35: 24.843366
B36: 46063 | C36: 321.4 | D36: 11.48909
B37: 46062 | C37: 322.8 | D37: 20.059198
B38: 46059 | C38: 325.8 | D38: 68.057745
B39: 46058 | C39: 310.2 | D39: 15.816704
B40: 46057 | C40: 313.85 | D40: 11.196759
B41: 46056 | C41: 316.65 | D41: 33.168353
...

Sheet Teaser
B2: ='Data Sheet'!B1& " - One Page Profile" -> ITC LTD - One Page Profile
C4: =Input!B2 -> ITC Limited is a leading Indian diversified company headquartered in Kolkata, established in 1910. It operates across multiple business segments including FMCG (foods and personal care), cigarettes, hotels, paper & packaging, and agri-business. While a large share of its profits still comes from the cigarette segment, its FMCG division is growing rapidly with popular brands like Aashirvaad and Sunfeast.The company has a strong distribution network across India and focuses on sustainability initiatives.
B5: INR (Crs.)
B6: Key Financial Matrics | C6: ='Profit & Loss'!G3 -> 44286 | D6: ='Profit & Loss'!H3 -> 44651 | E6: ='Profit & Loss'!I3 -> 45016 | F6: ='Profit & Loss'!J3 -> 45382 | G6: ='Profit & Loss'!K3 -> 45747 | I6: Share Price - 1years
B8: Total Sales | C8: ='Profit & Loss'!G4 -> 49257.45 | D8: ='Profit & Loss'!H4 -> 60644.54 | E8: ='Profit & Loss'!I4 -> 70919.03 | F8: ='Profit & Loss'!J4 -> 67931.94 | G8: ='Profit & Loss'!K4 -> 75323.34
B9: Sales Growth (y-o-y) | C9: ='Profit & Loss'!G27 -> -0.0026372963 | D9: ='Profit & Loss'!H27 -> 0.23117498 | E9: ='Profit & Loss'!I27 -> 0.16942152 | F9: ='Profit & Loss'!J27 -> -0.042119724 | G9: ='Profit & Loss'!K27 -> 0.10880596
B10: Gross Profit Margin (%) | C10: ='Profit & Loss'!G30 -> 0.51867748 | D10: ='Profit & Loss'!H30 -> 0.49650026 | E10: ='Profit & Loss'!I30 -> 0.53068887 | F10: ='Profit & Loss'!J30 -> 0.54582484 | G10: ='Profit & Loss'!K30 -> 0.51209373
B11: EBITDA Margin (%) | C11: ='Profit & Loss'!G32 -> 0.34644059 | D11: ='Profit & Loss'!H32 -> 0.34006606 | E11: ='Profit & Loss'!I32 -> 0.36244517 | F11: ='Profit & Loss'!J32 -> 0.37077596 | G11: ='Profit & Loss'!K32 -> 0.34304706
B12: EBIT Margin (%) | C12: ='Profit & Loss'!G34 -> 0.31303265 | D12: ='Profit & Loss'!H34 -> 0.31149944 | E12: ='Profit & Loss'!I34 -> 0.33693707 | F12: ='Profit & Loss'!J34 -> 0.34842932 | G12: ='Profit & Loss'!K34 -> 0.32119035
B13: Net Profit Margin (%) | C13: ='Profit & Loss'!G36 -> 0.26719187 | D13: ='Profit & Loss'!H36 -> 0.25134431 | E13: ='Profit & Loss'!I36 -> 0.27061368 | F13: ='Profit & Loss'!J36 -> 0.30116584 | G13: ='Profit & Loss'!K36 -> 0.46129964
B14: Earnings Per share (In Rs.) | C14: ='Profit & Loss'!G13 -> 10.692505 | D14: ='Profit & Loss'!H13 -> 12.368976 | E14: ='Profit & Loss'!I13 -> 15.442276 | F14: ='Profit & Loss'!J13 -> 16.387082 | G14: ='Profit & Loss'!K13 -> 27.765984
B15: EPS Growth (y-o-y) | C15: ='Profit & Loss'!G38 -> -0.14130126 | D15: ='Profit & Loss'!H38 -> 0.15678939 | E15: ='Profit & Loss'!I38 -> 0.2484684 | F15: ='Profit & Loss'!J38 -> 0.0611831 | G15: ='Profit & Loss'!K38 -> 0.69438246
B16: Dividend Per share (In Rs.) | C16: ='Profit & Loss'!G40 -> 10.75 | D16: ='Profit & Loss'!H40 -> 11.500004 | E16: ='Profit & Loss'!I40 -> 15.5 | F16: ='Profit & Loss'!J40 -> 13.749998 | G16: ='Profit & Loss'!K40 -> 14.349997
B17: Dividend Growth (y-o-y) | C17: ='Profit & Loss'!G41 -> 0.059113555 | D17: ='Profit & Loss'!H41 -> 0.069767819 | E17: ='Profit & Loss'!I41 -> 0.34782561 | F17: ='Profit & Loss'!J41 -> -0.11290335 | G17: ='Profit & Loss'!K41 -> 0.043636312
B19: Key Financial Ratios | C19: =C6 -> 44286 | D19: =D6 -> 44651 | E19: =E6 -> 45016 | F19: =F6 -> 45382 | G19: =G6 -> 45747 | I19: Volume - 1years (In milions)
B21: ='Profit & Loss'!A14 -> Price to earning | C21: ='Profit & Loss'!G14 -> 19.155475 | D21: ='Profit & Loss'!H14 -> 18.995914 | E21: ='Profit & Loss'!I14 -> 23.2796 | F21: ='Profit & Loss'!J14 -> 24.502837 | G21: ='Profit & Loss'!K14 -> 14.757266
B22: ='Profit & Loss'!A48 -> Ev/EBITDA | C22: ='Profit & Loss'!G48 -> 14.516487 | D22: ='Profit & Loss'!H48 -> 13.826369 | E22: ='Profit & Loss'!I48 -> 17.203375 | F22: ='Profit & Loss'!J48 -> 19.628122 | G22: ='Profit & Loss'!K48 -> 19.70001
B23: ='Profit & Loss'!A49 -> EV/Sales | C23: ='Profit & Loss'!G49 -> 5.0291002 | D23: ='Profit & Loss'!H49 -> 4.7018788 | E23: ='Profit & Loss'!I49 -> 6.2352802 | F23: ='Profit & Loss'!J49 -> 7.2776357 | G23: ='Profit & Loss'!K49 -> 6.7580305
B24: Price to Book Value | C24: ='Profit & Loss'!G51 -> 4.1776297 | D24: ='Profit & Loss'!H51 -> 4.6360678 | E24: ='Profit & Loss'!I51 -> 6.460451 | F24: ='Profit & Loss'!J51 -> 6.7282022 | G24: ='Profit & Loss'!K51 -> 7.3220746
B25: ='Balance Sheet'!A23 -> Return on Equity | C25: ='Balance Sheet'!G23 -> 0.21809064 | D25: ='Balance Sheet'!H23 -> 0.24405605 | E25: ='Balance Sheet'!I23 -> 0.27751555 | F25: ='Balance Sheet'!J23 -> 0.2745887 | G25: ='Balance Sheet'!K23 -> 0.49616743
B26: ='Balance Sheet'!A24 -> Return on Capital Emp | C26: ='Balance Sheet'!G24 -> 0.28527066 | D26: ='Balance Sheet'!H24 -> 0.33733253 | E26: ='Balance Sheet'!I24 -> 0.39333609 | F26: ='Balance Sheet'!J24 -> 0.37429273 | G26: ='Balance Sheet'!K24 -> 0.57864605
B28: Top 10 Shareholders | C28: ='Input Sheet'!G16 -> No.of Share (In crs.) | E28: ='Input Sheet'!H16 -> % Holding | F28: ='Input Sheet'!I16 -> Market Value (In Crs.) | I28: Share Holding Pattern
B30: Tobacco Manufacturers (India) Limited | C30: ='Input Sheet'!G17 -> 222.84959 | E30: ='Input Sheet'!H17 -> 0.1779 | F30: ='Input Sheet'!I17 -> 64938.369
B31: Life Insurance Corporation of India | C31: ='Input Sheet'!G18 -> 196.57974 | E31: ='Input Sheet'!H18 -> 0.1569 | F31: ='Input Sheet'!I18 -> 57283.335
B32: Specified Undertaking of the Unit Trust of India | C32: ='Input Sheet'!G19 -> 97.453143 | E32: ='Input Sheet'!H19 -> 0.0778 | F32: ='Input Sheet'!I19 -> 28397.846
B33: Myddleton Investment Company Limited | C33: ='Input Sheet'!G20 -> 48.631194 | E33: ='Input Sheet'!H20 -> 0.0388 | F33: ='Input Sheet'!I20 -> 14171.13
B34: SBI Mutual Funds | C34: ='Input Sheet'!G21 -> 41.195289 | E34: ='Input Sheet'!H21 -> 0.0329 | F34: ='Input Sheet'!I21 -> 12004.307
B35: ICICI Prudential Mutual Funds | C35: ='Input Sheet'!G22 -> 38.82518 | E35: ='Input Sheet'!H22 -> 0.031 | F35: ='Input Sheet'!I22 -> 11313.658
B36: QIB - Insurance Company Registered | C36: ='Input Sheet'!G23 -> 31.281378 | E36: ='Input Sheet'!H23 -> 0.025 | F36: ='Input Sheet'!I23 -> 9115.3936
B37: GQG Partners Emerging Markets Equity Fund | C37: ='Input Sheet'!G24 -> 22.380053 | E37: ='Input Sheet'!H24 -> 0.0179 | F37: ='Input Sheet'!I24 -> 6521.5474
B38: General Insurance Corporation of India | C38: ='Input Sheet'!G25 -> 21.708551 | E38: ='Input Sheet'!H25 -> 0.0173 | F38: ='Input Sheet'!I25 -> 6325.8717
B39: NPS Trust (various Pension Funds) | C39: ='Input Sheet'!G26 -> 20.23053 | E39: ='Input Sheet'!H26 -> 0.0162 | F39: ='Input Sheet'!I26 -> 5895.1763
B41: Managerial Remuneration | C41: Designation | D41: Remuneration | F41: X Median of Salary | I41: Capital Structure
B43: S Puri | C43: CMD | D43: 25.66 | F43: 377:1 | I43: Share Price as on 1-4-2026 | L43: ='Data Sheet'!B8 -> 293.15
B44: S Dutta | C44: ED & & CEO | D44: 8.53 | F44: 132:1 | I44: Number of Share O/s | L44: ='Data Sheet'!B6 -> 1252.9466
B45: H Malik | C45: ED | D45: 4.94 | F45: 99:1 | I45: Market Capitallization | L45: =L43*L44 -> 367301.31
B46: B Sumant | C46: ED | D46: 1.81 | F46: 174:1 | I46: Less: Cash & Equivalents | L46: ='Data Sheet'!K69*-1 -> -4012.36
I47: Add: Total Debt | L47: ='Data Sheet'!K59 -> 284.54
I48: Add: Non-controlling Interest | L48: 367.89
I49: Enterprise Value | L49: =SUM(L45:L48) -> 363941.38
...

Sheet Data>

Sheet Data Sheet
A1: COMPANY NAME | B1: ITC LTD | E1: =IF(B2<>B3, "A NEW VERSION OF THE WORKSHEET IS AVAILABLE", "")
A2: LATEST VERSION | B2: 2.1 | E2: PLEASE DO NOT MAKE ANY CHANGES TO THIS SHEET
A3: CURRENT VERSION | B3: 2.1
A5: META
A6: Number of shares | B6: =IF(B9>0, B9/B8, 0) -> 1252.9466
A7: Face Value | B7: 1
A8: Current Price | B8: 293.15
A9: Market Capitalization | B9: 367301.31
A15: PROFIT & LOSS
A16: Report Date | B16: 42460 | C16: 42825 | D16: 43190 | E16: 43555 | F16: 43921 | G16: 44286 | H16: 44651 | I16: 45016 | J16: 45382 | K16: 45747
A17: Sales | B17: 39192.1 | C17: 42767.6 | D17: 43448.94 | E17: 48339.58 | F17: 49387.7 | G17: 49257.45 | H17: 60644.54 | I17: 70919.03 | J17: 67931.94 | K17: 75323.34
A18: Raw Material Cost | B18: 13763.88 | C18: 15456.59 | D18: 14827.72 | E18: 17623.52 | F18: 18048.6 | G18: 20776.71 | H18: 27071.07 | I18: 29364.36 | J18: 27348.57 | K18: 32704.37
A19: Change in Inventory | B19: 195.38 | C19: -592.57 | D19: -1027.76 | E19: 203.19 | F19: 703.13 | G19: 645.27 | H19: 686 | I19: 358.59 | J19: 367.77 | K19: 725.65
A20: Power and Fuel | B20: 571.88 | C20: 584.33 | D20: 653.5 | E20: 746.73 | F20: 780.85 | G20: 699.56 | H20: 889.77 | I20: 1232.34 | J20: 952.9 | K20: 975.35
A21: Other Mfr. Exp | B21: 1581.59 | C21: 1683.9 | D21: 1697.62 | E21: 1871.01 | F21: 1908.29 | G21: 1587.18 | H21: 1887.67 | I21: 2327.8 | J21: 2183.76 | K21: 2345.36
A22: Employee Cost | B22: 3440.97 | C22: 3631.73 | D22: 3760.9 | E22: 4177.88 | F22: 4295.79 | G22: 4463.33 | H22: 4890.55 | I22: 5736.22 | J22: 5548.53 | K22: 6169.78
A23: Selling and admin | B23: 4261.78 | C23: 4179.74 | D23: 3954.87 | E23: 4546.39 | F23: 4488.63 | G23: 4236.77 | H23: 4858.38 | I23: 5604.08 | J23: 5312.45 | K23: 5793.29
A24: Other Expenses | B24: 1235.89 | C24: 1169.23 | D24: 1005.98 | E24: 1039.85 | F24: 1225.13 | G24: 1074.39 | H24: 1109.95 | I24: 1308.56 | J24: 1765.97 | K24: 2221.39
A25: Other Income | B25: 1483.11 | C25: 1758.63 | D25: 2239.81 | E25: 2080.44 | F25: 2417.32 | G25: 2576.95 | H25: 1909.72 | I25: 2097.64 | J25: 3330.45 | K25: 17794.88
A26: Depreciation | B26: 1077.4 | C26: 1152.79 | D26: 1236.28 | E26: 1396.61 | F26: 1644.91 | G26: 1645.59 | H26: 1732.41 | I26: 1809.01 | J26: 1518.05 | K26: 1646.32
A27: Interest | B27: 78.13 | C27: 49.03 | D27: 115.01 | E27: 71.4 | F27: 81.38 | G27: 57.97 | H27: 59.99 | I27: 77.77 | J27: 39.11 | K27: 45.06
... A31: Dividend Amount | B31: 6840.12 | C31: 5770.02 | D31: 6285.21 | E31: 7048.7 | F31: 12476.58 | G31: 13231.96 | H31: 14171.8 | I31: 19263.4 | J31: 17166.46 | K31: 17957.73
A40: Quarters
A41: Report Date | B41: 45199 | C41: 45291 | D41: 45382 | E41: 45473 | F41: 45565 | G41: 45657 | H41: 45747 | I41: 45838 | J41: 45930 | K41: 46022
A42: Sales | B42: 17774.47 | C42: 17195.24 | D42: 17037.8 | E42: 17777.81 | F42: 19990.36 | G42: 18790.17 | H42: 18765 | I42: 21494.79 | J42: 19501.63 | K42: 20047.3
A43: Expenses | B43: 11320.23 | C43: 10985.01 | D43: 10735.73 | E43: 11232.97 | F43: 13438.28 | G43: 12428.27 | H43: 12245.61 | I43: 14678.32 | J43: 12806.94 | K43: 13164.78
A44: Other Income | B44: 673.5 | C44: 820.26 | D44: 868 | E44: 771.13 | F44: 690.31 | G44: 803.4 | H44: 15391.28 | I44: 750.97 | J44: 738.84 | K44: 321.85
A45: Depreciation | B45: 453.04 | C45: 384.04 | D45: 385.09 | E45: 403.13 | F45: 416.18 | G45: 415.98 | H45: 411.03 | I45: 422.96 | J45: 434.8 | K45: 430.82
A46: Interest | B46: 9.87 | C46: 11.94 | D46: 10.72 | E46: 9.6 | F46: 14.73 | G46: 9.82 | H46: 10.91 | I46: 16.47 | J46: 20.05 | K46: 19.47
A47: Profit before tax | B47: 6664.83 | C47: 6634.51 | D47: 6774.26 | E47: 6903.24 | F47: 6811.48 | G47: 6739.5 | H47: 21488.73 | I47: 7128.01 | J47: 6978.68 | K47: 6754.08
A48: Tax | B48: 1700.31 | C48: 1227.99 | D48: 1583.55 | E48: 1726.25 | F48: 1757.05 | G48: 1726.32 | H48: 1680.85 | I48: 1784.6 | J48: 1792.13 | K48: 1735.63
A49: Net profit | B49: 4898.07 | C49: 5335.23 | D49: 5120.55 | E49: 5091.59 | F49: 4992.87 | G49: 4934.8 | H49: 19727.37 | I49: 5244.2 | J49: 5126.11 | K49: 4931.19
A50: Operating Profit | B50: 6454.24 | C50: 6210.23 | D50: 6302.07 | E50: 6544.84 | F50: 6552.08 | G50: 6361.9 | H50: 6519.39 | I50: 6816.47 | J50: 6694.69 | K50: 6882.52
A55: BALANCE SHEET
A56: Report Date | B56: 42460 | C56: 42825 | D56: 43190 | E56: 43555 | F56: 43921 | G56: 44286 | H56: 44651 | I56: 45016 | J56: 45382 | K56: 45747
A57: Equity Share Capital | B57: 804.72 | C57: 1214.74 | D57: 1220.43 | E57: 1225.86 | F57: 1229.22 | G57: 1230.88 | H57: 1232.33 | I57: 1242.8 | J57: 1248.47 | K57: 1251.41
A58: Reserves | B58: 41874.8 | C58: 45198.19 | D58: 51289.68 | E58: 57915.01 | F58: 64044.04 | G58: 59116.46 | H58: 61223.24 | I58: 67912.46 | J58: 73258.53 | K58: 68778.64
A59: Borrowings | B59: 83.78 | C59: 45.72 | D59: 35.92 | E59: 13.44 | F59: 277.45 | G59: 270.83 | H59: 249.44 | I59: 306.04 | J59: 303.43 | K59: 284.54
A60: Other Liabilities | B60: 8888.04 | C60: 9439.67 | D60: 11694.85 | E60: 12584.73 | F60: 11760.04 | G60: 13142.59 | H60: 14491.01 | I60: 16369.66 | J60: 16943.54 | K60: 17688.11
A61: Total | B61: 51651.34 | C61: 55898.32 | D61: 64240.88 | E61: 71739.04 | F61: 77310.75 | G61: 73760.76 | H61: 77196.02 | I61: 85830.96 | J61: 91753.97 | K61: 88002.7
...

Sheet Balance Sheet
A1: ='Profit & Loss'!A1 -> ITC LTD | E1: =UPDATE | J1: SCREENER.IN
A3: Narration | B3: ='Data Sheet'!B56 -> 42460 | C3: ='Data Sheet'!C56 -> 42825 | D3: ='Data Sheet'!D56 -> 43190 | E3: ='Data Sheet'!E56 -> 43555 | F3: ='Data Sheet'!F56 -> 43921 | G3: ='Data Sheet'!G56 -> 44286 | H3: ='Data Sheet'!H56 -> 44651 | I3: ='Data Sheet'!I56 -> 45016 | ... K3: ='Data Sheet'!K56 -> 45747
A4: Equity Share Capital | B4: ='Data Sheet'!B57 -> 804.72 | C4: ='Data Sheet'!C57 -> 1214.74 | D4: ='Data Sheet'!D57 -> 1220.43 | E4: ='Data Sheet'!E57 -> 1225.86 | F4: ='Data Sheet'!F57 -> 1229.22 | G4: ='Data Sheet'!G57 -> 1230.88 | H4: ='Data Sheet'!H57 -> 1232.33 | I4: ='Data Sheet'!I57 -> 1242.8 | ... K4: ='Data Sheet'!K57 -> 1251.41
A5: Reserves | B5: ='Data Sheet'!B58 -> 41874.8 | C5: ='Data Sheet'!C58 -> 45198.19 | D5: ='Data Sheet'!D58 -> 51289.68 | E5: ='Data Sheet'!E58 -> 57915.01 | F5: ='Data Sheet'!F58 -> 64044.04 | G5: ='Data Sheet'!G58 -> 59116.46 | H5: ='Data Sheet'!H58 -> 61223.24 | I5: ='Data Sheet'!I58 -> 67912.46 | ... K5: ='Data Sheet'!K58 -> 68778.64
A6: Borrowings | B6: ='Data Sheet'!B59 -> 83.78 | C6: ='Data Sheet'!C59 -> 45.72 | D6: ='Data Sheet'!D59 -> 35.92 | E6: ='Data Sheet'!E59 -> 13.44 | F6: ='Data Sheet'!F59 -> 277.45 | G6: ='Data Sheet'!G59 -> 270.83 | H6: ='Data Sheet'!H59 -> 249.44 | I6: ='Data Sheet'!I59 -> 306.04 | ... K6: ='Data Sheet'!K59 -> 284.54
A7: Other Liabilities | B7: ='Data Sheet'!B60 -> 8888.04 | C7: ='Data Sheet'!C60 -> 9439.67 | D7: ='Data Sheet'!D60 -> 11694.85 | E7: ='Data Sheet'!E60 -> 12584.73 | F7: ='Data Sheet'!F60 -> 11760.04 | G7: ='Data Sheet'!G60 -> 13142.59 | H7: ='Data Sheet'!H60 -> 14491.01 | I7: ='Data Sheet'!I60 -> 16369.66 | ... K7: ='Data Sheet'!K60 -> 17688.11
A8: Total | B8: ='Data Sheet'!B61 -> 51651.34 | C8: ='Data Sheet'!C61 -> 55898.32 | D8: ='Data Sheet'!D61 -> 64240.88 | E8: ='Data Sheet'!E61 -> 71739.04 | F8: ='Data Sheet'!F61 -> 77310.75 | G8: ='Data Sheet'!G61 -> 73760.76 | H8: ='Data Sheet'!H61 -> 77196.02 | I8: ='Data Sheet'!I61 -> 85830.96 | ... K8: ='Data Sheet'!K61 -> 88002.7
A10: Net Block | B10: ='Data Sheet'!B62 -> 15106.63 | C10: ='Data Sheet'!C62 -> 15893.48 | D10: ='Data Sheet'!D62 -> 16523.96 | E10: ='Data Sheet'!E62 -> 19374.19 | F10: ='Data Sheet'!F62 -> 21713.34 | G10: ='Data Sheet'!G62 -> 23298.48 | H10: ='Data Sheet'!H62 -> 24231.59 | I10: ='Data Sheet'!I62 -> 25851.27 | ... K10: ='Data Sheet'!K62 -> 21954.85
A11: Capital Work in Progress | B11: ='Data Sheet'!B63 -> 2559.72 | C11: ='Data Sheet'!C63 -> 3729.89 | D11: ='Data Sheet'!D63 -> 5508.33 | E11: ='Data Sheet'!E63 -> 4136.42 | F11: ='Data Sheet'!F63 -> 3256.46 | G11: ='Data Sheet'!G63 -> 4011.29 | H11: ='Data Sheet'!H63 -> 3225.54 | I11: ='Data Sheet'!I63 -> 3003.3 | ... K11: ='Data Sheet'!K63 -> 1090.91
A12: Investments | B12: ='Data Sheet'!B64 -> 11747.59 | C12: ='Data Sheet'!C64 -> 17581.38 | D12: ='Data Sheet'!D64 -> 22052.86 | E12: ='Data Sheet'!E64 -> 25043.49 | F12: ='Data Sheet'!F64 -> 28663.35 | G12: ='Data Sheet'!G64 -> 24870.87 | H12: ='Data Sheet'!H64 -> 24841.01 | I12: ='Data Sheet'!I64 -> 29415.02 | ... K12: ='Data Sheet'!K64 -> 34719.82
A13: Other Assets | B13: ='Data Sheet'!B65 -> 22237.4 | C13: ='Data Sheet'!C65 -> 18693.57 | D13: ='Data Sheet'!D65 -> 20155.73 | E13: ='Data Sheet'!E65 -> 23184.94 | F13: ='Data Sheet'!F65 -> 23677.6 | G13: ='Data Sheet'!G65 -> 21580.12 | H13: ='Data Sheet'!H65 -> 24897.88 | I13: ='Data Sheet'!I65 -> 27561.37 | ... K13: ='Data Sheet'!K65 -> 30237.12
A14: Total | B14: ='Data Sheet'!B66 -> 51651.34 | C14: ='Data Sheet'!C66 -> 55898.32 | D14: ='Data Sheet'!D66 -> 64240.88 | E14: ='Data Sheet'!E66 -> 71739.04 | F14: ='Data Sheet'!F66 -> 77310.75 | G14: ='Data Sheet'!G66 -> 73760.76 | H14: ='Data Sheet'!H66 -> 77196.02 | I14: ='Data Sheet'!I66 -> 85830.96 | ... K14: ='Data Sheet'!K66 -> 88002.7
A16: Working Capital | B16: =B13-B7 -> 13349.36 | C16: =C13-C7 -> 9253.9 | D16: =D13-D7 -> 8460.88 | E16: =E13-E7 -> 10600.21 | F16: =F13-F7 -> 11917.56 | G16: =G13-G7 -> 8437.53 | H16: =H13-H7 -> 10406.87 | I16: =I13-I7 -> 11191.71 | ... K16: =K13-K7 -> 12549.01
A17: Debtors | B17: ='Data Sheet'!B67 -> 1917.18 | C17: ='Data Sheet'!C67 -> 2474.29 | D17: ='Data Sheet'!D67 -> 2682.29 | E17: ='Data Sheet'!E67 -> 4035.28 | F17: ='Data Sheet'!F67 -> 2562.48 | G17: ='Data Sheet'!G67 -> 2501.7 | H17: ='Data Sheet'!H67 -> 2461.9 | I17: ='Data Sheet'!I67 -> 2956.17 | ... K17: ='Data Sheet'!K67 -> 4719.67
A18: Inventory | B18: ='Data Sheet'!B68 -> 9062.1 | C18: ='Data Sheet'!C68 -> 8116.1 | D18: ='Data Sheet'!D68 -> 7495.09 | E18: ='Data Sheet'!E68 -> 7859.56 | F18: ='Data Sheet'!F68 -> 8879.33 | G18: ='Data Sheet'!G68 -> 10397.16 | H18: ='Data Sheet'!H68 -> 10864.15 | I18: ='Data Sheet'!I68 -> 11771.16 | ... K18: ='Data Sheet'!K68 -> 15637.56
A20: Debtor Days | B20: =IF('Profit & Loss'!B4>0,'Balance Sheet'!B17/('Profit & Loss'!B4/365),0) -> 17.854892 | C20: =IF('Profit & Loss'!C4>0,'Balance Sheet'!C17/('Profit & Loss'!C4/365),0) -> 21.116823 | D20: =IF('Profit & Loss'!D4>0,'Balance Sheet'!D17/('Profit & Loss'!D4/365),0) -> 22.53302 | E20: =IF('Profit & Loss'!E4>0,'Balance Sheet'!E17/('Profit & Loss'!E4/365),0) -> 30.469383 | F20: =IF('Profit & Loss'!F4>0,'Balance Sheet'!F17/('Profit & Loss'!F4/365),0) -> 18.938019 | G20: =IF('Profit & Loss'!G4>0,'Balance Sheet'!G17/('Profit & Loss'!G4/365),0) -> 18.537714 | H20: =IF('Profit & Loss'!H4>0,'Balance Sheet'!H17/('Profit & Loss'!H4/365),0) -> 14.817385 | I20: =IF('Profit & Loss'!I4>0,'Balance Sheet'!I17/('Profit & Loss'!I4/365),0) -> 15.214563 | ... K20: =IF('Profit & Loss'!K4>0,'Balance Sheet'!K17/('Profit & Loss'!K4/365),0) -> 22.870462
A21: Inventory Turnover | B21: =IF('Balance Sheet'!B18>0,'Profit & Loss'!B4/'Balance Sheet'!B18,0) -> 4.3248364 | C21: =IF('Balance Sheet'!C18>0,'Profit & Loss'!C4/'Balance Sheet'!C18,0) -> 5.2694767 | D21: =IF('Balance Sheet'!D18>0,'Profit & Loss'!D4/'Balance Sheet'!D18,0) -> 5.7969871 | E21: =IF('Balance Sheet'!E18>0,'Profit & Loss'!E4/'Balance Sheet'!E18,0) -> 6.1504181 | F21: =IF('Balance Sheet'!F18>0,'Profit & Loss'!F4/'Balance Sheet'!F18,0) -> 5.5620976 | G21: =IF('Balance Sheet'!G18>0,'Profit & Loss'!G4/'Balance Sheet'!G18,0) -> 4.737587 | H21: =IF('Balance Sheet'!H18>0,'Profit & Loss'!H4/'Balance Sheet'!H18,0) -> 5.5820787 | I21: =IF('Balance Sheet'!I18>0,'Profit & Loss'!I4/'Balance Sheet'!I18,0) -> 6.0248123 | ... K21: =IF('Balance Sheet'!K18>0,'Profit & Loss'!K4/'Balance Sheet'!K18,0) -> 4.8168218
A23: Return on Equity | B23: =IF(SUM('Balance Sheet'!B4:B5)>0,'Profit & Loss'!B12/SUM('Balance Sheet'!B4:B5),"") -> 0.21894459 | C23: =IF(SUM('Balance Sheet'!C4:C5)>0,'Profit & Loss'!C12/SUM('Balance Sheet'!C4:C5),"") -> 0.22169339 | D23: =IF(SUM('Balance Sheet'!D4:D5)>0,'Profit & Loss'!D12/SUM('Balance Sheet'!D4:D5),"") -> 0.21464819 | E23: =IF(SUM('Balance Sheet'!E4:E5)>0,'Profit & Loss'!E12/SUM('Balance Sheet'!E4:E5),"") -> 0.21292095 | F23: =IF(SUM('Balance Sheet'!F4:F5)>0,'Profit & Loss'!F12/SUM('Balance Sheet'!F4:F5),"") -> 0.23449465 | G23: =IF(SUM('Balance Sheet'!G4:G5)>0,'Profit & Loss'!G12/SUM('Balance Sheet'!G4:G5),"") -> 0.21809064 | H23: =IF(SUM('Balance Sheet'!H4:H5)>0,'Profit & Loss'!H12/SUM('Balance Sheet'!H4:H5),"") -> 0.24405605 | I23: =IF(SUM('Balance Sheet'!I4:I5)>0,'Profit & Loss'!I12/SUM('Balance Sheet'!I4:I5),"") -> 0.27751555 | ... K23: =IF(SUM('Balance Sheet'!K4:K5)>0,'Profit & Loss'!K12/SUM('Balance Sheet'!K4:K5),"") -> 0.49616743
A24: Return on Capital Emp | C24: =IF((B4+B5+B6+C4+C5+C6)>0,('Profit & Loss'!C10+'Profit & Loss'!C9)*2/(B4+B5+B6+C4+C5+C6),"") -> 0.36034518 | D24: =IF((C4+C5+C6+D4+D5+D6)>0,('Profit & Loss'!D10+'Profit & Loss'!D9)*2/(C4+C5+C6+D4+D5+D6),"") -> 0.35400589 | E24: =IF((D4+D5+D6+E4+E5+E6)>0,('Profit & Loss'!E10+'Profit & Loss'!E9)*2/(D4+D5+D6+E4+E5+E6),"") -> 0.34415688 | F24: =IF((E4+E5+E6+F4+F5+F6)>0,('Profit & Loss'!F10+'Profit & Loss'!F9)*2/(E4+E5+E6+F4+F5+F6),"") -> 0.32261652 | G24: =IF((F4+F5+F6+G4+G5+G6)>0,('Profit & Loss'!G10+'Profit & Loss'!G9)*2/(F4+F5+F6+G4+G5+G6),"") -> 0.28527066 | H24: =IF((G4+G5+G6+H4+H5+H6)>0,('Profit & Loss'!H10+'Profit & Loss'!H9)*2/(G4+G5+G6+H4+H5+H6),"") -> 0.33733253 | I24: =IF((H4+H5+H6+I4+I5+I6)>0,('Profit & Loss'!I10+'Profit & Loss'!I9)*2/(H4+H5+H6+I4+I5+I6),"") -> 0.39333609 | J24: =IF((I4+I5+I6+J4+J5+J6)>0,('Profit & Loss'!J10+'Profit & Loss'!J9)*2/(I4+I5+I6+J4+J5+J6),"") -> 0.37429273 | K24: =IF((J4+J5+J6+K4+K5+K6)>0,('Profit & Loss'!K10+'Profit & Loss'!K9)*2/(J4+J5+J6+K4+K5+K6),"") -> 0.57864605
A26: Book Value | B26: =B4+B5 -> 42679.52 | C26: =C4+C5 -> 46412.93 | D26: =D4+D5 -> 52510.11 | E26: =E4+E5 -> 59140.87 | F26: =F4+F5 -> 65273.26 | G26: =G4+G5 -> 60347.34 | H26: =H4+H5 -> 62455.57 | I26: =I4+I5 -> 69155.26 | ... K26: =K4+K5 -> 70030.05

Sheet Profit & Loss
A1: ='Data Sheet'!B1 -> ITC LTD | H1: =UPDATE | M1: SCREENER.IN
A3: Narration | B3: ='Data Sheet'!B16 -> 42460 | C3: ='Data Sheet'!C16 -> 42825 | D3: ='Data Sheet'!D16 -> 43190 | E3: ='Data Sheet'!E16 -> 43555 | F3: ='Data Sheet'!F16 -> 43921 | G3: ='Data Sheet'!G16 -> 44286 | H3: ='Data Sheet'!H16 -> 44651 | I3: ='Data Sheet'!I16 -> 45016 | ... K3: ='Data Sheet'!K16 -> 45747 | L3: Trailing | M3: Best Case | N3: Worst Case
A4: Sales | B4: ='Data Sheet'!B17 -> 39192.1 | C4: ='Data Sheet'!C17 -> 42767.6 | D4: ='Data Sheet'!D17 -> 43448.94 | E4: ='Data Sheet'!E17 -> 48339.58 | F4: ='Data Sheet'!F17 -> 49387.7 | G4: ='Data Sheet'!G17 -> 49257.45 | H4: ='Data Sheet'!H17 -> 60644.54 | I4: ='Data Sheet'!I17 -> 70919.03 | ... K4: ='Data Sheet'!K17 -> 75323.34 | L4: =SUM(#REF!) -> #REF! | M4: =$K4+M23*K4 -> 80967.151 | N4: =$K4+N23*L4 -> #REF!
A5: Expenses | B5: =SUM('Data Sheet'!B18,'Data Sheet'!B20:B24, -1*'Data Sheet'!B19) -> 24660.61 | C5: =SUM('Data Sheet'!C18,'Data Sheet'!C20:C24, -1*'Data Sheet'!C19) -> 27298.09 | D5: =SUM('Data Sheet'!D18,'Data Sheet'!D20:D24, -1*'Data Sheet'!D19) -> 26928.35 | E5: =SUM('Data Sheet'!E18,'Data Sheet'!E20:E24, -1*'Data Sheet'!E19) -> 29802.19 | F5: =SUM('Data Sheet'!F18,'Data Sheet'!F20:F24, -1*'Data Sheet'!F19) -> 30044.16 | G5: =SUM('Data Sheet'!G18,'Data Sheet'!G20:G24, -1*'Data Sheet'!G19) -> 32192.67 | H5: =SUM('Data Sheet'!H18,'Data Sheet'!H20:H24, -1*'Data Sheet'!H19) -> 40021.39 | I5: =SUM('Data Sheet'!I18,'Data Sheet'!I20:I24, -1*'Data Sheet'!I19) -> 45214.77 | ... K5: =SUM('Data Sheet'!K18,'Data Sheet'!K20:K24, -1*'Data Sheet'!K19) -> 49483.89 | L5: =SUM(#REF!) -> #REF! | M5: =M4-M6 -> #REF! | N5: =N4-N6 -> #REF!
A6: Operating Profit | B6: =B4-B5 -> 14531.49 | C6: =C4-C5 -> 15469.51 | D6: =D4-D5 -> 16520.59 | E6: =E4-E5 -> 18537.39 | F6: =F4-F5 -> 19343.54 | G6: =G4-G5 -> 17064.78 | H6: =H4-H5 -> 20623.15 | I6: =I4-I5 -> 25704.26 | ... K6: =K4-K5 -> 25839.45 | L6: =SUM(#REF!) -> #REF! | M6: =M4*M24 -> #REF! | N6: =N4*N24 -> #REF!
A7: Other Income | B7: ='Data Sheet'!B25 -> 1483.11 | C7: ='Data Sheet'!C25 -> 1758.63 | D7: ='Data Sheet'!D25 -> 2239.81 | E7: ='Data Sheet'!E25 -> 2080.44 | F7: ='Data Sheet'!F25 -> 2417.32 | G7: ='Data Sheet'!G25 -> 2576.95 | H7: ='Data Sheet'!H25 -> 1909.72 | I7: ='Data Sheet'!I25 -> 2097.64 | ... K7: ='Data Sheet'!K25 -> 17794.88 | L7: =SUM(#REF!) -> #REF! | M7: 0 | N7: 0
A8: Depreciation | B8: ='Data Sheet'!B26 -> 1077.4 | C8: ='Data Sheet'!C26 -> 1152.79 | D8: ='Data Sheet'!D26 -> 1236.28 | E8: ='Data Sheet'!E26 -> 1396.61 | F8: ='Data Sheet'!F26 -> 1644.91 | G8: ='Data Sheet'!G26 -> 1645.59 | H8: ='Data Sheet'!H26 -> 1732.41 | I8: ='Data Sheet'!I26 -> 1809.01 | ... K8: ='Data Sheet'!K26 -> 1646.32 | L8: =SUM(#REF!) -> #REF! | M8: =+$L8 -> #REF! | N8: =+$L8 -> #REF!
A9: Interest | B9: ='Data Sheet'!B27 -> 78.13 | C9: ='Data Sheet'!C27 -> 49.03 | D9: ='Data Sheet'!D27 -> 115.01 | E9: ='Data Sheet'!E27 -> 71.4 | F9: ='Data Sheet'!F27 -> 81.38 | G9: ='Data Sheet'!G27 -> 57.97 | H9: ='Data Sheet'!H27 -> 59.99 | I9: ='Data Sheet'!I27 -> 77.77 | ... K9: ='Data Sheet'!K27 -> 45.06 | L9: =SUM(#REF!) -> #REF! | M9: =+$L9 -> #REF! | N9: =+$L9 -> #REF!
A10: Profit before tax | B10: ='Data Sheet'!B28 -> 14859.07 | C10: ='Data Sheet'!C28 -> 16026.32 | D10: ='Data Sheet'!D28 -> 17409.11 | E10: ='Data Sheet'!E28 -> 19149.82 | F10: ='Data Sheet'!F28 -> 20034.57 | G10: ='Data Sheet'!G28 -> 17938.17 | H10: ='Data Sheet'!H28 -> 20740.47 | I10: ='Data Sheet'!I28 -> 25915.12 | ... K10: ='Data Sheet'!K28 -> 41942.95 | L10: =SUM(#REF!) -> #REF! | M10: =M6+M7-SUM(M8:M9) -> #REF! | N10: =N6+N7-SUM(N8:N9) -> #REF!
A11: Tax | B11: ='Data Sheet'!B29 -> 5358.21 | C11: ='Data Sheet'!C29 -> 5549.09 | D11: ='Data Sheet'!D29 -> 5916.43 | E11: ='Data Sheet'!E29 -> 6313.92 | F11: ='Data Sheet'!F29 -> 4441.79 | G11: ='Data Sheet'!G29 -> 4555.29 | H11: ='Data Sheet'!H29 -> 5237.34 | I11: ='Data Sheet'!I29 -> 6438.4 | ... K11: ='Data Sheet'!K29 -> 6890.47 | L11: =SUM(#REF!) -> #REF! | M11: =IF($L10>0,$L11/$L10,0) -> #REF! | N11: =IF($L10>0,$L11/$L10,0) -> #REF!
A12: Net profit | B12: ='Data Sheet'!B30 -> 9344.45 | C12: ='Data Sheet'!C30 -> 10289.44 | D12: ='Data Sheet'!D30 -> 11271.2 | E12: ='Data Sheet'!E30 -> 12592.33 | F12: ='Data Sheet'!F30 -> 15306.23 | G12: ='Data Sheet'!G30 -> 13161.19 | H12: ='Data Sheet'!H30 -> 15242.66 | I12: ='Data Sheet'!I30 -> 19191.66 | ... K12: ='Data Sheet'!K30 -> 34746.63 | L12: =SUM(#REF!) -> #REF! | M12: =M10-M11*M10 -> #REF! | N12: =N10-N11*N10 -> #REF!
A13: EPS | B13: =IF('Data Sheet'!B93>0,B12/'Data Sheet'!B93,0) -> 7.7413676 | C13: =IF('Data Sheet'!C93>0,C12/'Data Sheet'!C93,0) -> 8.4704875 | D13: =IF('Data Sheet'!D93>0,D12/'Data Sheet'!D93,0) -> 9.2354334 | E13: =IF('Data Sheet'!E93>0,E12/'Data Sheet'!E93,0) -> 10.272242 | F13: =IF('Data Sheet'!F93>0,F12/'Data Sheet'!F93,0) -> 12.451986 | G13: =IF('Data Sheet'!G93>0,G12/'Data Sheet'!G93,0) -> 10.692505 | H13: =IF('Data Sheet'!H93>0,H12/'Data Sheet'!H93,0) -> 12.368976 | I13: =IF('Data Sheet'!I93>0,I12/'Data Sheet'!I93,0) -> 15.442276 | ... K13: =IF('Data Sheet'!K93>0,K12/'Data Sheet'!K93,0) -> 27.765984 | L13: =IF('Data Sheet'!$B6>0,'Profit & Loss'!L12/'Data Sheet'!$B6,0) -> #REF! | M13: =IF('Data Sheet'!$B6>0,'Profit & Loss'!M12/'Data Sheet'!$B6,0) -> #REF! | N13: =IF('Data Sheet'!$B6>0,'Profit & Loss'!N12/'Data Sheet'!$B6,0) -> #REF!
A14: Price to earning | B14: =IF(B15>0,B15/B13,"") -> 26.497902 | C14: =IF(C15>0,C15/C13,"") -> 31.019466 | D14: =IF(D15>0,D15/D13,"") -> 25.93273 | E14: =IF(E15>0,E15/E13,"") -> 27.12553 | F14: =IF(F15>0,F15/F13,"") -> 12.925649 | G14: =IF(G15>0,G15/G13,"") -> 19.155475 | H14: =IF(H15>0,H15/H13,"") -> 18.995914 | I14: =IF(I15>0,I15/I13,"") -> 23.2796 | ... K14: =IF(K15>0,K15/K13,"") -> 14.757266 | L14: =IF(L13>0,L15/L13,0) -> #REF! | M14: =M25 -> #REF! | N14: =N25 -> #REF!
A15: Price | B15: ='Data Sheet'!B90 -> 205.13 | C15: ='Data Sheet'!C90 -> 262.75 | D15: ='Data Sheet'!D90 -> 239.5 | E15: ='Data Sheet'!E90 -> 278.64 | F15: ='Data Sheet'!F90 -> 160.95 | G15: ='Data Sheet'!G90 -> 204.82 | H15: ='Data Sheet'!H90 -> 234.96 | I15: ='Data Sheet'!I90 -> 359.49 | ... K15: ='Data Sheet'!K90 -> 409.75 | L15: ='Data Sheet'!B8 -> 293.15 | M15: =M13*M14 -> #REF! | N15: =N13*N14 -> #REF!
A17: RATIOS:
A18: Dividend Payout | B18: =IF('Data Sheet'!B30>0, 'Data Sheet'!B31/'Data Sheet'!B30, 0) -> 0.73199814 | C18: =IF('Data Sheet'!C30>0, 'Data Sheet'!C31/'Data Sheet'!C30, 0) -> 0.56077104 | D18: =IF('Data Sheet'!D30>0, 'Data Sheet'!D31/'Data Sheet'!D30, 0) -> 0.5576345 | E18: =IF('Data Sheet'!E30>0, 'Data Sheet'!E31/'Data Sheet'!E30, 0) -> 0.55976138 | F18: =IF('Data Sheet'!F30>0, 'Data Sheet'!F31/'Data Sheet'!F30, 0) -> 0.81513083 | G18: =IF('Data Sheet'!G30>0, 'Data Sheet'!G31/'Data Sheet'!G30, 0) -> 1.0053772 | H18: =IF('Data Sheet'!H30>0, 'Data Sheet'!H31/'Data Sheet'!H30, 0) -> 0.92974586 | I18: =IF('Data Sheet'!I30>0, 'Data Sheet'!I31/'Data Sheet'!I30, 0) -> 1.0037381 | ... K18: =IF('Data Sheet'!K30>0, 'Data Sheet'!K31/'Data Sheet'!K30, 0) -> 0.51681933
A19: OPM | B19: =IF(B6>0,B6/B4,0) -> 0.370776 | C19: =IF(C6>0,C6/C4,0) -> 0.36171097 | D19: =IF(D6>0,D6/D4,0) -> 0.38022999 | E19: =IF(E6>0,E6/E4,0) -> 0.38348265 | F19: =IF(F6>0,F6/F4,0) -> 0.39166716 | G19: =IF(G6>0,G6/G4,0) -> 0.34644059 | H19: =IF(H6>0,H6/H4,0) -> 0.34006606 | I19: =IF(I6>0,I6/I4,0) -> 0.36244517 | ... L19: =IF(L6>0,L6/L4,0) -> #REF!
G22: TRENDS: | H22: 10 YEARS | I22: 7 YEARS | J22: 5 YEARS | K22: 3 YEARS | L22: RECENT | M22: BEST | N22: WORST
G23: Sales Growth | H23: =IF(B4=0,"",POWER($K4/B4,1/9)-1) -> 0.075290157 | I23: =IF(D4=0,"",POWER($K4/D4,1/7)-1) -> 0.081772082 | J23: =IF(F4=0,"",POWER($K4/F4,1/5)-1) -> 0.088083322 | K23: =IF(H4=0,"",POWER($K4/H4, 1/3)-1) -> 0.074927782 | L23: =IF(ISERROR(MAX(IF(J4=0,"",(K4-J4)/J4),IF(K4=0,"",(L4-K4)/K4))),"",MAX(IF(J4=0,"",(K4-J4)/J4),IF(K4=0,"",(L4-K4)/K4))) | M23: =MAX(K23:L23) -> 0.074927782 | N23: =MIN(H23:L23) -> 0.074927782
G24: OPM | H24: =IF(SUM(B4:$K$4)=0,"",SUMPRODUCT(B19:$K$19,B4:$K$4)/SUM(B4:$K$4)) -> 0.36333562 | I24: =IF(SUM(E4:$K$4)=0,"",SUMPRODUCT(E19:$K$19,E4:$K$4)/SUM(E4:$K$4)) -> 0.36106877 | J24: =IF(SUM(G4:$K$4)=0,"",SUMPRODUCT(G19:$K$19,G4:$K$4)/SUM(G4:$K$4)) -> 0.35306244 | K24: =IF(SUM(I4:$K$4)=0, "", SUMPRODUCT(I19:$K$19,I4:$K$4)/SUM(I4:$K$4)) -> 0.35826538 | L24: =L19 -> #REF! | M24: =MAX(K24:L24) -> #REF! | N24: =MIN(H24:L24) -> #REF!
G25: Price to Earning | H25: =IF(ISERROR(AVERAGEIF(B14:$L14,">0")),"",AVERAGEIF(B14:$L14,">0")) -> 22.419237 | I25: =IF(ISERROR(AVERAGEIF(E14:$L14,">0")),"",AVERAGEIF(E14:$L14,">0")) -> 20.106039 | J25: =IF(ISERROR(AVERAGEIF(G14:$L14,">0")),"",AVERAGEIF(G14:$L14,">0")) -> 20.138218 | K25: =IF(ISERROR(AVERAGEIF(I14:$L14,">0")),"",AVERAGEIF(I14:$L14,">0")) -> 20.846568 | L25: =L14 -> #REF! | M25: =MAX(K25:L25) -> #REF! | N25: =MIN(H25:L25) -> #REF!
A27: Sales Growth Y-O-Y | C27: =C4/B4-1 -> 0.09123012 | D27: =D4/C4-1 -> 0.015931219 | E27: =E4/D4-1 -> 0.11256063 | F27: =F4/E4-1 -> 0.021682439 | G27: =G4/F4-1 -> -0.0026372963 | H27: =H4/G4-1 -> 0.23117498 | I27: =I4/H4-1 -> 0.16942152 | J27: =J4/I4-1 -> -0.042119724 | K27: =K4/J4-1 -> 0.10880596
A29: Gross Profit | B29: ='Data Sheet'!B17-'Data Sheet'!B18-'Data Sheet'!B19-'Data Sheet'!B20-'Data Sheet'!B21 -> 23079.37 | C29: ='Data Sheet'!C17-'Data Sheet'!C18-'Data Sheet'!C19-'Data Sheet'!C20-'Data Sheet'!C21 -> 25635.35 | D29: ='Data Sheet'!D17-'Data Sheet'!D18-'Data Sheet'!D19-'Data Sheet'!D20-'Data Sheet'!D21 -> 27297.86 | E29: ='Data Sheet'!E17-'Data Sheet'!E18-'Data Sheet'!E19-'Data Sheet'!E20-'Data Sheet'!E21 -> 27895.13 | F29: ='Data Sheet'!F17-'Data Sheet'!F18-'Data Sheet'!F19-'Data Sheet'!F20-'Data Sheet'!F21 -> 27946.83 | G29: ='Data Sheet'!G17-'Data Sheet'!G18-'Data Sheet'!G19-'Data Sheet'!G20-'Data Sheet'!G21 -> 25548.73 | H29: ='Data Sheet'!H17-'Data Sheet'!H18-'Data Sheet'!H19-'Data Sheet'!H20-'Data Sheet'!H21 -> 30110.03 | I29: ='Data Sheet'!I17-'Data Sheet'!I18-'Data Sheet'!I19-'Data Sheet'!I20-'Data Sheet'!I21 -> 37635.94 | ... K29: ='Data Sheet'!K17-'Data Sheet'!K18-'Data Sheet'!K19-'Data Sheet'!K20-'Data Sheet'!K21 -> 38572.61
A30: GPM | B30: =B29/B4 -> 0.58887812 | C30: =C29/C4 -> 0.59941054 | D30: =D29/D4 -> 0.62827448 | E30: =E29/E4 -> 0.57706604 | F30: =F29/F4 -> 0.5658662 | G30: =G29/G4 -> 0.51867748 | H30: =H29/H4 -> 0.49650026 | I30: =I29/I4 -> 0.53068887 | ... K30: =K29/K4 -> 0.51209373
A32: EBITDA Margin (%) | B32: =B6/B4 -> 0.370776 | C32: =C6/C4 -> 0.36171097 | D32: =D6/D4 -> 0.38022999 | E32: =E6/E4 -> 0.38348265 | F32: =F6/F4 -> 0.39166716 | G32: =G6/G4 -> 0.34644059 | H32: =H6/H4 -> 0.34006606 | I32: =I6/I4 -> 0.36244517 | ... K32: =K6/K4 -> 0.34304706
A34: EBIT Margin (%) | B34: =(B6-B8)/B4 -> 0.34328576 | C34: =(C6-C8)/C4 -> 0.33475622 | D34: =(D6-D8)/D4 -> 0.35177636 | E34: =(E6-E8)/E4 -> 0.354591 | F34: =(F6-F8)/F4 -> 0.35836109 | G34: =(G6-G8)/G4 -> 0.31303265 | H34: =(H6-H8)/H4 -> 0.31149944 | I34: =(I6-I8)/I4 -> 0.33693707 | ... K34: =(K6-K8)/K4 -> 0.32119035
A36: Net Profit Margin (%) | B36: =B12/B4 -> 0.23842688 | C36: =C12/C4 -> 0.24058961 | D36: =D12/D4 -> 0.25941254 | E36: =E12/E4 -> 0.2604973 | F36: =F12/F4 -> 0.30991988 | G36: =G12/G4 -> 0.26719187 | H36: =H12/H4 -> 0.25134431 | I36: =I12/I4 -> 0.27061368 | ... K36: =K12/K4 -> 0.46129964
A38: EPS Growth (Y-O-Y) | C38: =C13/B13-1 -> 0.094184898 | D38: =D13/C13-1 -> 0.090307187 | E38: =E13/D13-1 -> 0.11226415 | F38: =F13/E13-1 -> 0.21219753 | G38: =G13/F13-1 -> -0.14130126 | H38: =H13/G13-1 -> 0.15678939 | I38: =I13/H13-1 -> 0.2484684 | J38: =J13/I13-1 -> 0.0611831 | K38: =K13/J13-1 -> 0.69438246
A40: Dividend Per share (In Rs.) | B40: =B13*B18 -> 5.6666667 | C40: =C13*C18 -> 4.7500041 | D40: =D13*D18 -> 5.1499963 | E40: =E13*E18 -> 5.7500041 | F40: =F13*F18 -> 10.149998 | G40: =G13*G18 -> 10.75 | H40: =H13*H18 -> 11.500004 | I40: =I13*I18 -> 15.5 | ... K40: =K13*K18 -> 14.349997
A41: Dividend Growth (Y-O-Y) | C41: =C40/B40-1 -> -0.16176398 | D41: =D40/C40-1 -> 0.084208811 | E41: =E40/D40-1 -> 0.11650645 | F41: =F40/E40-1 -> 0.76521571 | G41: =G40/F40-1 -> 0.059113555 | H41: =H40/G40-1 -> 0.069767819 | I41: =I40/H40-1 -> 0.34782561 | J41: =J40/I40-1 -> -0.11290335 | K41: =K40/J40-1 -> 0.043636312
A43: market Capitalization | B43: ='Data Sheet'!B93*'Data Sheet'!B90 -> 247608.32 | C43: ='Data Sheet'!C93*'Data Sheet'!C90 -> 319172.93 | D43: ='Data Sheet'!D93*'Data Sheet'!D90 -> 292292.99 | E43: ='Data Sheet'!E93*'Data Sheet'!E90 -> 341573.63 | F43: ='Data Sheet'!F93*'Data Sheet'!F90 -> 197842.96 | G43: ='Data Sheet'!G93*'Data Sheet'!G90 -> 252108.84 | H43: ='Data Sheet'!H93*'Data Sheet'!H90 -> 289548.26 | I43: ='Data Sheet'!I93*'Data Sheet'!I90 -> 446774.17 | ... K43: ='Data Sheet'!K93*'Data Sheet'!K90 -> 512765.25
A44: Debt | B44: ='Balance Sheet'!B6 -> 83.78 | C44: ='Balance Sheet'!C6 -> 45.72 | D44: ='Balance Sheet'!D6 -> 35.92 | E44: ='Balance Sheet'!E6 -> 13.44 | F44: ='Balance Sheet'!F6 -> 277.45 | G44: ='Balance Sheet'!G6 -> 270.83 | H44: ='Balance Sheet'!H6 -> 249.44 | I44: ='Balance Sheet'!I6 -> 306.04 | ... K44: ='Balance Sheet'!K6 -> 284.54
A45: Cash | B45: ='Data Sheet'!B69 -> 6063.3 | C45: ='Data Sheet'!C69 -> 2967.4 | D45: ='Data Sheet'!D69 -> 2899.6 | E45: ='Data Sheet'!E69 -> 4152.03 | F45: ='Data Sheet'!F69 -> 7277.34 | G45: ='Data Sheet'!G69 -> 4659.02 | H45: ='Data Sheet'!H69 -> 4654.42 | I45: ='Data Sheet'!I69 -> 4880.19 | ... K45: ='Data Sheet'!K69 -> 4012.36
A46: EV | B46: =B43+B44-B45 -> 241628.8 | C46: =C43+C44-C45 -> 316251.25 | D46: =D43+D44-D45 -> 289429.31 | E46: =E43+E44-E45 -> 337435.04 | F46: =F43+F44-F45 -> 190843.07 | G46: =G43+G44-G45 -> 247720.65 | H46: =H43+H44-H45 -> 285143.28 | I46: =I43+I44-I45 -> 442200.02 | ... K46: =K43+K44-K45 -> 509037.43
A48: Ev/EBITDA | B48: =B46/B6 -> 16.627944 | C48: =C46/C6 -> 20.443521 | D48: =D46/D6 -> 17.519308 | E48: =E46/E6 -> 18.202942 | F48: =F46/F6 -> 9.8659847 | G48: =G46/G6 -> 14.516487 | H48: =H46/H6 -> 13.826369 | I48: =I46/I6 -> 17.203375 | ... K48: =K46/K6 -> 19.70001
A49: EV/Sales | B49: =B46/B4 -> 6.1652425 | C49: =C46/C4 -> 7.3946458 | D49: =D46/D4 -> 6.6613663 | E49: =E46/E4 -> 6.9805125 | F49: =F46/F4 -> 3.8641822 | G49: =G46/G4 -> 5.0291002 | H49: =H46/H4 -> 4.7018788 | I49: =I46/I4 -> 6.2352802 | ... K49: =K46/K4 -> 6.7580305
A51: P/B | B51: =B43/'Balance Sheet'!B26 -> 5.8015723 | C51: =C43/'Balance Sheet'!C26 -> 6.8768107 | D51: =D43/'Balance Sheet'!D26 -> 5.5664135 | E51: =E43/'Balance Sheet'!E26 -> 5.7755936 | F51: =F43/'Balance Sheet'!F26 -> 3.0309955 | G51: =G43/'Balance Sheet'!G26 -> 4.1776297 | H51: =H43/'Balance Sheet'!H26 -> 4.6360678 | I51: =I43/'Balance Sheet'!I26 -> 6.460451 | ... K51: =K43/'Balance Sheet'!K26 -> 7.3220746
